Workbook

Sheet Param_estimation
B2: Decay rates per lap | D2: MAX Laps | E2: MIN Stints | G2: Fuel Estimation
B3: Fuel | C3: =100-practice_data_belgium_final!I2 -> 3.3704138 | D3: =(120/C3) -> 35.603937 | E3: =_xlfn.CEILING.MATH(63/D3) -> 2 | G3: AVG Max Fuel | H3: {=AVERAGE(_xlfn.NUMBERVALUE(practice_data_belgium_final!L82:L85))} -> 102.98339
B4: Extra soft | C4: =100-practice_data_belgium_final!J90 -> 5.982234 | D4: =(100/C4) -> 16.716163 | E4: =_xlfn.CEILING.MATH(63/D4) -> 4 | G4: AVG Min Fuel | H4: {=AVERAGE(_xlfn.NUMBERVALUE(practice_data_belgium_final!L86:L89))} -> 93.563347
B5: Soft | C5: =100-practice_data_belgium_final!J98 -> 3.9235406 | D5: =(100/C5) -> 25.487184 | E5: =_xlfn.CEILING.MATH(63/D5) -> 3 | G5: Fuel Diff (s) | H5: =H3-H4 -> 9.420044
B6: Medium | C6: =100-practice_data_belgium_final!J106 -> 3.4209229 | D6: =(100/C6) -> 29.231878 | E6: =_xlfn.CEILING.MATH(63/D6) -> 3 | G6: Max Laps | H6: =120/C3 -> 35.603937
B7: Hard | C7: =100-practice_data_belgium_final!J114 -> 3.1874023 | D7: =(100/C7) -> 31.37351 | E7: =_xlfn.CEILING.MATH(63/D7) -> 3 | G7: Fuel Penalty per Lap | H7: =H5/H6 -> 0.26457872
G8: Fuel Penalty per Liter | H8: =H5/116 -> 0.081207276
B11: Tire | C11: Seconds lost per lap | D11: Basepace Estimation | G11: Fuel Calculator
B12: Extra Soft | C12: {=SLOPE(_xlfn.NUMBERVALUE(practice_data_belgium_final!L90:L97),_xlfn.NUMBERVALUE(practice_data_belgium_final!B90:B97)) + H7} -> -0.10440688 | D12: =AVERAGE(practice_data_belgium_final!M90:M97) -> 92.594006 | G12: Rounds | H12: 16
B13: Soft | C13: {=SLOPE(_xlfn.NUMBERVALUE(practice_data_belgium_final!L98:L105),_xlfn.NUMBERVALUE(practice_data_belgium_final!B98:B105)) + H7} -> 0.032319311 | D13: =AVERAGE(practice_data_belgium_final!M98:M105) -> 93.407381 | G13: Fuel needed | H13: =_xlfn.CEILING.MATH(0.01 + H12*C3) -> 54
B14: Medium | C14: {=SLOPE(_xlfn.NUMBERVALUE(practice_data_belgium_final!L106:L113),_xlfn.NUMBERVALUE(practice_data_belgium_final!B106:B113)) +H7} -> -0.075490212 | D14: =AVERAGE(practice_data_belgium_final!M106:M113) -> 93.428835 | G14: Fuel in last Round | H14: =H13-H12*C3 -> 0.073379214
B15: Hard | C15: {=SLOPE(_xlfn.NUMBERVALUE(practice_data_belgium_final!L114:L121),_xlfn.NUMBERVALUE(practice_data_belgium_final!B114:B121)) + H7} -> 0.10118836 | D15: =AVERAGE(practice_data_belgium_final!M114:M121) -> 93.638097
A18: Strategy: 3x SOFT | H18: Strategy: 1x MEDIUM, 1x SOFT, 1x EXTRA SOFT
A21: Stint | B21: Lap | C21: Fuel | D21: Tyre | E21: Compound | F21: Time | H21: Stint | I21: Lap | J21: Fuel | K21: Tyre | L21: Compound | M21: Time
A22: 1 | B22: 1 | C22: =71-$C$3 -> 67.629586 | D22: =100-$C$5 -> 96.076459 | E22: Soft | F22: =$D$13+C22*$H$8 -> 98.899396 | H22: 1 | I22: 1 | J22: =81-$C$3 -> 77.629586 | K22: =100-$C$6 -> 96.579077 | L22: Medium | M22: =$D$14+J22*$H$8 -> 99.732922
A23: 2 | B23: 2 | C23: =C22-$C$3 -> 64.259172 | D23: =D22-$C$5 -> 92.152919 | E23: Soft | F23: =$D$13+C23*$H$8 -> 98.625693 | H23: 2 | I23: 2 | J23: =J22-$C$3 -> 74.259172 | K23: =K22-$C$6 -> 93.158154 | L23: Medium | M23: =$D$14+J23*$H$8 -> 99.45922
A24: 3 | B24: 3 | C24: =C23-$C$3 -> 60.888759 | D24: =D23-$C$5 -> 88.229378 | E24: Soft | F24: =$D$13+C24*$H$8 -> 98.351991 | H24: 3 | I24: 3 | J24: =J23-$C$3 -> 70.888759 | K24: =K23-$C$6 -> 89.737231 | L24: Medium | M24: =$D$14+J24*$H$8 -> 99.185518
A25: 4 | B25: 4 | C25: =C24-$C$3 -> 57.518345 | D25: =D24-$C$5 -> 84.305838 | E25: Soft | F25: =$D$13+C25*$H$8 -> 98.078289 | H25: 4 | I25: 4 | J25: =J24-$C$3 -> 67.518345 | K25: =K24-$C$6 -> 86.316308 | L25: Medium | M25: =$D$14+J25*$H$8 -> 98.911815
A26: 5 | B26: 5 | C26: =C25-$C$3 -> 54.147931 | D26: =D25-$C$5 -> 80.382297 | E26: Soft | F26: =$D$13+C26*$H$8 -> 97.804587 | H26: 5 | I26: 5 | J26: =J25-$C$3 -> 64.147931 | K26: =K25-$C$6 -> 82.895385 | L26: Medium | M26: =$D$14+J26*$H$8 -> 98.638113
A27: 6 | B27: 6 | C27: =C26-$C$3 -> 50.777517 | D27: =D26-$C$5 -> 76.458756 | E27: Soft | F27: =$D$13+C27*$H$8 -> 97.530885 | H27: 6 | I27: 6 | J27: =J26-$C$3 -> 60.777517 | K27: =K26-$C$6 -> 79.474462 | L27: Medium | M27: =$D$14+J27*$H$8 -> 98.364411
A28: 7 | B28: 7 | C28: =C27-$C$3 -> 47.407103 | D28: =D27-$C$5 -> 72.535216 | E28: Soft | F28: =$D$13+C28*$H$8 -> 97.257183 | H28: 7 | I28: 7 | J28: =J27-$C$3 -> 57.407103 | K28: =K27-$C$6 -> 76.05354 | L28: Medium | M28: =$D$14+J28*$H$8 -> 98.090709
A29: 8 | B29: 8 | C29: =C28-$C$3 -> 44.03669 | D29: =D28-$C$5 -> 68.611675 | E29: Soft | F29: =$D$13+C29*$H$8 -> 96.983481 | H29: 8 | I29: 8 | J29: =J28-$C$3 -> 54.03669 | K29: =K28-$C$6 -> 72.632617 | L29: Medium | M29: =$D$14+J29*$H$8 -> 97.817007
A30: 9 | B30: 9 | C30: =C29-$C$3 -> 40.666276 | D30: =D29-$C$5 -> 64.688135 | E30: Soft | F30: =$D$13+C30*$H$8 -> 96.709779 | H30: 9 | I30: 9 | J30: =J29-$C$3 -> 50.666276 | K30: =K29-$C$6 -> 69.211694 | L30: Medium | M30: =$D$14+J30*$H$8 -> 97.543305
A31: 10 | B31: 10 | C31: =C30-$C$3 -> 37.295862 | D31: =D30-$C$5 -> 60.764594 | E31: Soft | F31: =$D$13+C31*$H$8 -> 96.436076 | H31: 10 | I31: 10 | J31: =J30-$C$3 -> 47.295862 | K31: =K30-$C$6 -> 65.790771 | L31: Medium | M31: =$D$14+J31*$H$8 -> 97.269603
A32: 11 | B32: 11 | C32: =C31-$C$3 -> 33.925448 | D32: =D31-$C$5 -> 56.841053 | E32: Soft | F32: =$D$13+C32*$H$8 -> 96.162374 | H32: 11 | I32: 11 | J32: =J31-$C$3 -> 43.925448 | K32: =K31-$C$6 -> 62.369848 | L32: Medium | M32: =$D$14+J32*$H$8 -> 96.995901
A33: 12 | B33: 12 | C33: =C32-$C$3 -> 30.555034 | D33: =D32-$C$5 -> 52.917513 | E33: Soft | F33: =$D$13+C33*$H$8 -> 95.888672 | H33: 12 | I33: 12 | J33: =J32-$C$3 -> 40.555034 | K33: =K32-$C$6 -> 58.948925 | L33: Medium | M33: =$D$14+J33*$H$8 -> 96.722198
A34: 13 | B34: 13 | C34: =C33-$C$3 -> 27.184621 | D34: =D33-$C$5 -> 48.993972 | E34: Soft | F34: =$D$13+C34*$H$8 -> 95.61497 | H34: 13 | I34: 13 | J34: =J33-$C$3 -> 37.184621 | K34: =K33-$C$6 -> 55.528002 | L34: Medium | M34: =$D$14+J34*$H$8 -> 96.448496
... A42: 21 | B42: 21 | C42: =C41-$C$3 -> 0.22131022 | D42: =D41-$C$5 -> 17.605647 | E42: Soft | F42: =$D$13+C42*$H$8 -> 93.425353 | H42: 21 | I42: 21 | J42: =J41-$C$3 -> 10.22131 | K42: =K41-$C$6 -> 28.160619 | L42: Medium | M42: =$D$14+J42*$H$8 -> 94.258879
A43: 1 | B43: 22 | C43: =71-$C$3 -> 67.629586 | D43: =100-$C$5 -> 96.076459 | E43: Soft | F43: =$D$13+C43*$H$8 -> 98.899396 | H43: 22 | I43: 22 | J43: =J42-$C$3 -> 6.8508964 | K43: =K42-$C$6 -> 24.739696 | L43: Medium | M43: =$D$14+J43*$H$8 -> 93.985177
A44: 2 | B44: 23 | C44: =C43-$C$3 -> 64.259172 | D44: =D43-$C$5 -> 92.152919 | E44: Soft | F44: =$D$13+C44*$H$8 -> 98.625693 | H44: 23 | I44: 23 | J44: =J43-$C$3 -> 3.4804826 | K44: =K43-$C$6 -> 21.318773 | L44: Medium | M44: =$D$14+J44*$H$8 -> 93.711475
A45: 3 | B45: 24 | C45: =C44-$C$3 -> 60.888759 | D45: =D44-$C$5 -> 88.229378 | E45: Soft | F45: =$D$13+C45*$H$8 -> 98.351991 | H45: 24 | I45: 24 | J45: =J44-$C$3 -> 0.11006882 | K45: =K44-$C$6 -> 17.89785 | L45: Medium | M45: =$D$14+J45*$H$8 -> 93.437773
A46: 4 | B46: 25 | C46: =C45-$C$3 -> 57.518345 | D46: =D45-$C$5 -> 84.305838 | E46: Soft | F46: =$D$13+C46*$H$8 -> 98.078289 | H46: 1 | I46: 25 | J46: =78-$C$3 -> 74.629586 | K46: =100-$C$5 -> 96.076459 | L46: Soft | M46: =$D$13+J46*$H$8 -> 99.467847
A47: 5 | B47: 26 | C47: =C46-$C$3 -> 54.147931 | D47: =D46-$C$5 -> 80.382297 | E47: Soft | F47: =$D$13+C47*$H$8 -> 97.804587 | H47: 2 | I47: 26 | J47: =J46-$C$3 -> 71.259172 | K47: =K46-$C$5 -> 92.152919 | L47: Soft | M47: =$D$13+J47*$H$8 -> 99.194144
A48: 6 | B48: 27 | C48: =C47-$C$3 -> 50.777517 | D48: =D47-$C$5 -> 76.458756 | E48: Soft | F48: =$D$13+C48*$H$8 -> 97.530885 | H48: 3 | I48: 27 | J48: =J47-$C$3 -> 67.888759 | K48: =K47-$C$5 -> 88.229378 | L48: Soft | M48: =$D$13+J48*$H$8 -> 98.920442
A49: 7 | B49: 28 | C49: =C48-$C$3 -> 47.407103 | D49: =D48-$C$5 -> 72.535216 | E49: Soft | F49: =$D$13+C49*$H$8 -> 97.257183 | H49: 4 | I49: 28 | J49: =J48-$C$3 -> 64.518345 | K49: =K48-$C$5 -> 84.305838 | L49: Soft | M49: =$D$13+J49*$H$8 -> 98.64674
A50: 8 | B50: 29 | C50: =C49-$C$3 -> 44.03669 | D50: =D49-$C$5 -> 68.611675 | E50: Soft | F50: =$D$13+C50*$H$8 -> 96.983481 | H50: 5 | I50: 29 | J50: =J49-$C$3 -> 61.147931 | K50: =K49-$C$5 -> 80.382297 | L50: Soft | M50: =$D$13+J50*$H$8 -> 98.373038
A51: 9 | B51: 30 | C51: =C50-$C$3 -> 40.666276 | D51: =D50-$C$5 -> 64.688135 | E51: Soft | F51: =$D$13+C51*$H$8 -> 96.709779 | H51: 6 | I51: 30 | J51: =J50-$C$3 -> 57.777517 | K51: =K50-$C$5 -> 76.458756 | L51: Soft | M51: =$D$13+J51*$H$8 -> 98.099336
A52: 10 | B52: 31 | C52: =C51-$C$3 -> 37.295862 | D52: =D51-$C$5 -> 60.764594 | E52: Soft | F52: =$D$13+C52*$H$8 -> 96.436076 | H52: 7 | I52: 31 | J52: =J51-$C$3 -> 54.407103 | K52: =K51-$C$5 -> 72.535216 | L52: Soft | M52: =$D$13+J52*$H$8 -> 97.825634
A53: 11 | B53: 32 | C53: =C52-$C$3 -> 33.925448 | D53: =D52-$C$5 -> 56.841053 | E53: Soft | F53: =$D$13+C53*$H$8 -> 96.162374 | H53: 8 | I53: 32 | J53: =J52-$C$3 -> 51.03669 | K53: =K52-$C$5 -> 68.611675 | L53: Soft | M53: =$D$13+J53*$H$8 -> 97.551932
A54: 12 | B54: 33 | C54: =C53-$C$3 -> 30.555034 | D54: =D53-$C$5 -> 52.917513 | E54: Soft | F54: =$D$13+C54*$H$8 -> 95.888672 | H54: 9 | I54: 33 | J54: =J53-$C$3 -> 47.666276 | K54: =K53-$C$5 -> 64.688135 | L54: Soft | M54: =$D$13+J54*$H$8 -> 97.27823
...

Sheet practice_data_belgium_final
A1: Stint | B1: Lap | C1: Rear Wing | D1: Front Wing | E1: Engine | F1: Brake | G1: Differential | H1: Suspension | I1: Fuel | J1: Tyre Remaining | K1: Tyre Choice | L1: Lap Time | M1: Lap Time Helper | N1: Column1
A2: 1 | B2: 1 | C2: 441 | D2: 477 | E2: 50 | F2: 175 | G2: 179 | H2: 72 | I2: 96.629586200873 | J2: 96.07645939696 | K2: Soft | L2: 101.83281085
A3: 2 | B3: 1 | C3: 441 | D3: 477 | E3: 50 | F3: 175 | G3: 179 | H3: 72 | I3: 96.629586200873 | J3: 96.07645939696 | K3: Soft | L3: 99.98381085
A4: 3 | B4: 1 | C4: 480 | D4: 282 | E4: 47 | F4: 461 | G4: 88 | H4: 9 | I4: 96.629586200873 | J4: 96.07645939696 | K4: Soft | L4: 103.46893225
A5: 4 | B5: 1 | C5: 480 | D5: 282 | E5: 47 | F5: 461 | G5: 88 | H5: 9 | I5: 96.629586200873 | J5: 96.07645939696 | K5: Soft | L5: 104.54093225
A6: 5 | B6: 1 | C6: 482 | D6: 438 | E6: 109 | F6: 435 | G6: 62 | H6: 75 | I6: 96.629586200873 | J6: 96.07645939696 | K6: Soft | L6: 103.99743225
A7: 6 | B7: 1 | C7: 482 | D7: 438 | E7: 109 | F7: 435 | G7: 62 | H7: 75 | I7: 96.629586200873 | J7: 96.07645939696 | K7: Soft | L7: 102.87943225
A8: 7 | B8: 1 | C8: 399 | D8: 311 | E8: 16 | F8: 477 | G8: 106 | H8: 46 | I8: 96.629586200873 | J8: 96.07645939696 | K8: Soft | L8: 105.04853225
A9: 8 | B9: 1 | C9: 399 | D9: 311 | E9: 16 | F9: 477 | G9: 106 | H9: 46 | I9: 96.629586200873 | J9: 96.07645939696 | K9: Soft | L9: 104.87953225
A10: 9 | B10: 1 | C10: 380 | D10: 228 | E10: 100 | F10: 136 | G10: 93 | H10: 2 | I10: 96.629586200873 | J10: 96.07645939696 | K10: Soft | L10: 104.18695125
A11: 10 | B11: 1 | C11: 380 | D11: 228 | E11: 100 | F11: 136 | G11: 93 | H11: 2 | I11: 96.629586200873 | J11: 96.07645939696 | K11: Soft | L11: 103.78395125
A12: 11 | B12: 1 | C12: 476 | D12: 299 | E12: 34 | F12: 71 | G12: 119 | H12: 69 | I12: 96.629586200873 | J12: 96.07645939696 | K12: Soft | L12: 101.68650125
A13: 12 | B13: 1 | C13: 476 | D13: 299 | E13: 34 | F13: 71 | G13: 119 | H13: 69 | I13: 96.629586200873 | J13: 96.07645939696 | K13: Soft | L13: 102.62250125
... A89: 88 | B89: 1 | C89: 460 | D89: 480 | E89: 15 | F89: 306 | G89: 168 | H89: 23 | I89: 0.62958620087323 | J89: 96.07645939696 | K89: Soft | L89: 92.87584685
A90: 89 | B90: 1 | C90: 460 | D90: 480 | E90: 15 | F90: 306 | G90: 168 | H90: 23 | I90: 116.62958620087 | J90: 94.017766014074 | K90: Extra Soft | L90: 102.50489085 | M90: =practice_data_belgium_final[[#This Row],[Lap Time]] - Param_estimation!$H$5 + (practice_data_belgium_final[[#This Row],[Lap]]-1)*Param_estimation!$H$7 -> 93.084847 | N90: =120-practice_data_belgium_final[[#This Row],[Fuel]] -> 3.3704138
A91: 89 | B91: 2 | C91: 460 | D91: 480 | E91: 15 | F91: 306 | G91: 168 | H91: 23 | I91: 113.25917240175 | J91: 88.035532028148 | K91: Extra Soft | L91: 102.31175048992 | M91: =practice_data_belgium_final[[#This Row],[Lap Time]] - Param_estimation!$H$5 + (practice_data_belgium_final[[#This Row],[Lap]]-1)*Param_estimation!$H$7 -> 93.156285 | N91: =I90-practice_data_belgium_final[[#This Row],[Fuel]] -> 3.3704138
A92: 89 | B92: 3 | C92: 460 | D92: 480 | E92: 15 | F92: 306 | G92: 168 | H92: 23 | I92: 109.88875860262 | J92: 82.053298042222 | K92: Extra Soft | L92: 100.71361012984 | M92: =practice_data_belgium_final[[#This Row],[Lap Time]] - Param_estimation!$H$5 + (practice_data_belgium_final[[#This Row],[Lap]]-1)*Param_estimation!$H$7 -> 91.822724 | N92: =I91-practice_data_belgium_final[[#This Row],[Fuel]] -> 3.3704138
A93: 89 | B93: 4 | C93: 460 | D93: 480 | E93: 15 | F93: 306 | G93: 168 | H93: 23 | I93: 106.51834480349 | J93: 76.071064056297 | K93: Extra Soft | L93: 101.68746976977 | M93: =practice_data_belgium_final[[#This Row],[Lap Time]] - Param_estimation!$H$5 + (practice_data_belgium_final[[#This Row],[Lap]]-1)*Param_estimation!$H$7 -> 93.061162 | N93: =I92-practice_data_belgium_final[[#This Row],[Fuel]] -> 3.3704138
A94: 89 | B94: 5 | C94: 460 | D94: 480 | E94: 15 | F94: 306 | G94: 168 | H94: 23 | I94: 103.14793100437 | J94: 70.088830070371 | K94: Extra Soft | L94: 101.16332940969 | M94: =practice_data_belgium_final[[#This Row],[Lap Time]] - Param_estimation!$H$5 + (practice_data_belgium_final[[#This Row],[Lap]]-1)*Param_estimation!$H$7 -> 92.8016 | N94: =I93-practice_data_belgium_final[[#This Row],[Fuel]] -> 3.3704138
A95: 89 | B95: 6 | C95: 460 | D95: 480 | E95: 15 | F95: 306 | G95: 168 | H95: 23 | I95: 99.777517205239 | J95: 64.106596084445 | K95: Extra Soft | L95: 99.91218904961 | M95: =practice_data_belgium_final[[#This Row],[Lap Time]] - Param_estimation!$H$5 + (practice_data_belgium_final[[#This Row],[Lap]]-1)*Param_estimation!$H$7 -> 91.815039 | N95: =I94-practice_data_belgium_final[[#This Row],[Fuel]] -> 3.3704138
A96: 89 | B96: 7 | C96: 460 | D96: 480 | E96: 15 | F96: 306 | G96: 168 | H96: 23 | I96: 96.407103406113 | J96: 58.124362098519 | K96: Extra Soft | L96: 100.92504868953 | M96: =practice_data_belgium_final[[#This Row],[Lap Time]] - Param_estimation!$H$5 + (practice_data_belgium_final[[#This Row],[Lap]]-1)*Param_estimation!$H$7 -> 93.092477 | N96: =I95-practice_data_belgium_final[[#This Row],[Fuel]] -> 3.3704138
A97: 89 | B97: 8 | C97: 460 | D97: 480 | E97: 15 | F97: 306 | G97: 168 | H97: 23 | I97: 93.036689606986 | J97: 52.142128112593 | K97: Extra Soft | L97: 99.485908329455 | M97: =practice_data_belgium_final[[#This Row],[Lap Time]] - Param_estimation!$H$5 + (practice_data_belgium_final[[#This Row],[Lap]]-1)*Param_estimation!$H$7 -> 91.917915 | N97: =I96-practice_data_belgium_final[[#This Row],[Fuel]] -> 3.3704138
A98: 90 | B98: 1 | C98: 460 | D98: 480 | E98: 15 | F98: 306 | G98: 168 | H98: 23 | I98: 116.62958620087 | J98: 96.07645939696 | K98: Soft | L98: 102.50339085 | M98: =practice_data_belgium_final[[#This Row],[Lap Time]] - Param_estimation!$H$5 + (practice_data_belgium_final[[#This Row],[Lap]]-1)*Param_estimation!$H$7 -> 93.083347 | N98: =I97-practice_data_belgium_final[[#This Row],[Fuel]] -> -23.592897
A99: 90 | B99: 2 | C99: 460 | D99: 480 | E99: 15 | F99: 306 | G99: 168 | H99: 23 | I99: 113.25917240175 | J99: 92.15291879392 | K99: Soft | L99: 103.13625048992 | M99: =practice_data_belgium_final[[#This Row],[Lap Time]] - Param_estimation!$H$5 + (practice_data_belgium_final[[#This Row],[Lap]]-1)*Param_estimation!$H$7 -> 93.980785 | N99: =I98-practice_data_belgium_final[[#This Row],[Fuel]] -> 3.3704138
A100: 90 | B100: 3 | C100: 460 | D100: 480 | E100: 15 | F100: 306 | G100: 168 | H100: 23 | I100: 109.88875860262 | J100: 88.229378190879 | K100: Soft | L100: 102.03911012984 | M100: =practice_data_belgium_final[[#This Row],[Lap Time]] - Param_estimation!$H$5 + (practice_data_belgium_final[[#This Row],[Lap]]-1)*Param_estimation!$H$7 -> 93.148224 | N100: =I99-practice_data_belgium_final[[#This Row],[Fuel]] -> 3.3704138
A101: 90 | B101: 4 | C101: 460 | D101: 480 | E101: 15 | F101: 306 | G101: 168 | H101: 23 | I101: 106.51834480349 | J101: 84.305837587839 | K101: Soft | L101: 101.74096976977 | M101: =practice_data_belgium_final[[#This Row],[Lap Time]] - Param_estimation!$H$5 + (practice_data_belgium_final[[#This Row],[Lap]]-1)*Param_estimation!$H$7 -> 93.114662 | N101: =I100-practice_data_belgium_final[[#This Row],[Fuel]] -> 3.3704138
A102: 90 | B102: 5 | C102: 460 | D102: 480 | E102: 15 | F102: 306 | G102: 168 | H102: 23 | I102: 103.14793100437 | J102: 80.382296984799 | K102: Soft | L102: 102.02382940969 | M102: =practice_data_belgium_final[[#This Row],[Lap Time]] - Param_estimation!$H$5 + (practice_data_belgium_final[[#This Row],[Lap]]-1)*Param_estimation!$H$7 -> 93.6621 | N102: =I101-practice_data_belgium_final[[#This Row],[Fuel]] -> 3.3704138
... A121: 92 | B121: 8 | C121: 460 | D121: 480 | E121: 15 | F121: 306 | G121: 168 | H121: 23 | I121: 93.036689606986 | J121: 74.50078123882 | K121: Hard | L121: 101.09524882945 | M121: =practice_data_belgium_final[[#This Row],[Lap Time]] - Param_estimation!$H$5 + (practice_data_belgium_final[[#This Row],[Lap]]-1)*Param_estimation!$H$7 -> 93.527256 | N121: =I120-practice_data_belgium_final[[#This Row],[Fuel]] -> 3.3704138
